<?xml version="1.0" encoding="utf-8"?>
<!-- This URDF was automatically created by SolidWorks to URDF Exporter! Originally created by Stephen Brawner (brawner@gmail.com) 
     Commit Version: 1.6.0-4-g7f85cfe  Build Version: 1.6.7995.38578
     For more information, please see http://wiki.ros.org/sw_urdf_exporter -->
<robot
  name="walker_design_2">
  <link
    name="right_lower_leg_link">
    <inertial>
      <origin
        xyz="-0.061505 -0.0080541 0.06441"
        rpy="0 0 0" />
      <mass
        value="0.12388" />
      <inertia
        ixx="0.00012842"
        ixy="-1.7409E-06"
        ixz="4.6599E-07"
        iyy="8.2257E-05"
        iyz="8.2871E-07"
        izz="0.00015824" />
    </inertial>
    <visual>
      <origin
        xyz="0 0 0"
        rpy="0 0 0" />
      <geometry>
        <mesh
          filename="package://walker_design_2/meshes/right_lower_leg_link.STL" />
      </geometry>
      <material
        name="">
        <color
          rgba="0.79216 0.81961 0.93333 1" />
      </material>
    </visual>
    <collision>
      <origin
        xyz="0 0 0"
        rpy="0 0 0" />
      <geometry>
        <mesh
          filename="package://walker_design_2/meshes/right_lower_leg_link.STL" />
      </geometry>
    </collision>
  </link>
  <link
    name="right_upper_leg_link">
    <inertial>
      <origin
        xyz="-0.056283 0.0050019 0.14149"
        rpy="0 0 0" />
      <mass
        value="0.1014" />
      <inertia
        ixx="0.00011429"
        ixy="-1.4716E-06"
        ixz="-4.9936E-05"
        iyy="0.00021518"
        iyz="-4.8791E-07"
        izz="0.00010974" />
    </inertial>
    <visual>
      <origin
        xyz="0 0 0"
        rpy="0 0 0" />
      <geometry>
        <mesh
          filename="package://walker_design_2/meshes/right_upper_leg_link.STL" />
      </geometry>
      <material
        name="">
        <color
          rgba="0.79216 0.81961 0.93333 1" />
      </material>
    </visual>
    <collision>
      <origin
        xyz="0 0 0"
        rpy="0 0 0" />
      <geometry>
        <mesh
          filename="package://walker_design_2/meshes/right_upper_leg_link.STL" />
      </geometry>
    </collision>
  </link>
  <joint
    name="right_knee_joint"
    type="revolute">
    <origin
      xyz="-0.069 -0.035 0.23789"
      rpy="0.17453 0 0" />
    <parent
      link="right_lower_leg_link" />
    <child
      link="right_upper_leg_link" />
    <axis
      xyz="1 0 0" />
    <limit
      lower="0"
      upper="1.57"
      effort="0"
      velocity="0" />
  </joint>
  <link
    name="right_hip_link">
    <inertial>
      <origin
        xyz="-0.05 -5.5511E-17 -3.4694E-17"
        rpy="0 0 0" />
      <mass
        value="0.0028274" />
      <inertia
        ixx="5.7962E-08"
        ixy="-2.5837E-21"
        ixz="-1.7596E-21"
        iyy="2.3852E-06"
        iyz="4.702E-38"
        izz="2.3852E-06" />
    </inertial>
    <visual>
      <origin
        xyz="0 0 0"
        rpy="0 0 0" />
      <geometry>
        <mesh
          filename="package://walker_design_2/meshes/right_hip_link.STL" />
      </geometry>
      <material
        name="">
        <color
          rgba="0.79216 0.81961 0.93333 1" />
      </material>
    </visual>
    <collision>
      <origin
        xyz="0 0 0"
        rpy="0 0 0" />
      <geometry>
        <mesh
          filename="package://walker_design_2/meshes/right_hip_link.STL" />
      </geometry>
    </collision>
  </link>
  <joint
    name="right_hip_joint"
    type="revolute">
    <origin
      xyz="0.0052304 0 0.188"
      rpy="-0.17453 0 0" />
    <parent
      link="right_upper_leg_link" />
    <child
      link="right_hip_link" />
    <axis
      xyz="-1 0 0" />
    <limit
      lower="0"
      upper="0"
      effort="0"
      velocity="0" />
  </joint>
  <link
    name="left_hip_link">
    <inertial>
      <origin
        xyz="0.06164 0.037773 -0.027522"
        rpy="0 0 0" />
      <mass
        value="0.1014" />
      <inertia
        ixx="0.00011296"
        ixy="-4.4634E-05"
        ixz="2.407E-05"
        iyy="0.0001368"
        iyz="4.491E-05"
        izz="0.00018945" />
    </inertial>
    <visual>
      <origin
        xyz="0 0 0"
        rpy="0 0 0" />
      <geometry>
        <mesh
          filename="package://walker_design_2/meshes/left_hip_link.STL" />
      </geometry>
      <material
        name="">
        <color
          rgba="0.79216 0.81961 0.93333 1" />
      </material>
    </visual>
    <collision>
      <origin
        xyz="0 0 0"
        rpy="0 0 0" />
      <geometry>
        <mesh
          filename="package://walker_design_2/meshes/left_hip_link.STL" />
      </geometry>
    </collision>
  </link>
  <joint
    name="left_hip_joint"
    type="revolute">
    <origin
      xyz="-0.1 0 0"
      rpy="0 0 0" />
    <parent
      link="right_hip_link" />
    <child
      link="left_hip_link" />
    <axis
      xyz="-1 0 0" />
    <limit
      lower="0"
      upper="0"
      effort="0"
      velocity="0" />
  </joint>
  <link
    name="left_lower_leg_link">
    <inertial>
      <origin
        xyz="0.010495 -0.13677 -0.11008"
        rpy="0 0 0" />
      <mass
        value="0.12388" />
      <inertia
        ixx="0.00012842"
        ixy="-4.669E-07"
        ixz="1.7407E-06"
        iyy="0.00013996"
        iyz="3.2486E-05"
        izz="0.00010053" />
    </inertial>
    <visual>
      <origin
        xyz="0 0 0"
        rpy="0 0 0" />
      <geometry>
        <mesh
          filename="package://walker_design_2/meshes/left_lower_leg_link.STL" />
      </geometry>
      <material
        name="">
        <color
          rgba="0.79216 0.81961 0.93333 1" />
      </material>
    </visual>
    <collision>
      <origin
        xyz="0 0 0"
        rpy="0 0 0" />
      <geometry>
        <mesh
          filename="package://walker_design_2/meshes/left_lower_leg_link.STL" />
      </geometry>
    </collision>
  </link>
  <joint
    name="left_knee_joint"
    type="revolute">
    <origin
      xyz="0.014226 0.16281 -0.094"
      rpy="1.0472 0 0" />
    <parent
      link="left_hip_link" />
    <child
      link="left_lower_leg_link" />
    <axis
      xyz="1 0 0" />
    <limit
      lower="0"
      upper="1.57"
      effort="0"
      velocity="0" />
  </joint>
</robot>