<?xml version="1.0" encoding="utf-8"?>
<!-- This URDF was automatically created by SolidWorks to URDF Exporter! Originally created by Stephen Brawner (brawner@gmail.com) 
     Commit Version: 1.6.0-4-g7f85cfe  Build Version: 1.6.7995.38578
     For more information, please see http://wiki.ros.org/sw_urdf_exporter -->
<robot
  name="ramp_meshes_1">
  <link
    name="right_lower_leg_link">
    <inertial>
      <origin
        xyz="-0.0615053146451188 -0.008054147483954 0.0644104745433465"
        rpy="0 0 0" />
      <mass
        value="0.123883133217275" />
      <inertia
        ixx="0.000128415612995708"
        ixy="-1.74091858241873E-06"
        ixz="4.6598543660348E-07"
        iyy="8.22570949980407E-05"
        iyz="8.28711938867076E-07"
        izz="0.00015823792993869" />
    </inertial>
    <visual>
      <origin
        xyz="0 0 0"
        rpy="0 0 0" />
      <geometry>
        <mesh
          filename="package://ramp_meshes_1/meshes/right_lower_leg_link.STL" />
      </geometry>
      <material
        name="">
        <color
          rgba="0.792156862745098 0.819607843137255 0.933333333333333 1" />
      </material>
    </visual>
    <collision>
      <origin
        xyz="0 0 0"
        rpy="0 0 0" />
      <geometry>
        <mesh
          filename="package://ramp_meshes_1/meshes/right_lower_leg_link.STL" />
      </geometry>
    </collision>
  </link>
  <link
    name="right_upper_leg_link">
    <inertial>
      <origin
        xyz="-0.0562828876412978 0.00500191107012748 0.141489644097149"
        rpy="0 0 0" />
      <mass
        value="0.101399403255084" />
      <inertia
        ixx="0.000114286085966719"
        ixy="-1.47157629045173E-06"
        ixz="-4.99355146038688E-05"
        iyy="0.000215178375299073"
        iyz="-4.87911538527944E-07"
        izz="0.000109741610710701" />
    </inertial>
    <visual>
      <origin
        xyz="0 0 0"
        rpy="0 0 0" />
      <geometry>
        <mesh
          filename="package://ramp_meshes_1/meshes/right_upper_leg_link.STL" />
      </geometry>
      <material
        name="">
        <color
          rgba="0.792156862745098 0.819607843137255 0.933333333333333 1" />
      </material>
    </visual>
    <collision>
      <origin
        xyz="0 0 0"
        rpy="0 0 0" />
      <geometry>
        <mesh
          filename="package://ramp_meshes_1/meshes/right_upper_leg_link.STL" />
      </geometry>
    </collision>
  </link>
  <joint
    name="right_knee_joint"
    type="revolute">
    <origin
      xyz="-0.069 -0.035 0.23789"
      rpy="0.17453 0 0" />
    <parent
      link="right_lower_leg_link" />
    <child
      link="right_upper_leg_link" />
    <axis
      xyz="1 0 0" />
    <limit
      lower="0"
      upper="1.57"
      effort="0"
      velocity="0" />
  </joint>
  <link
    name="right_hip_link">
    <inertial>
      <origin
        xyz="-0.1 -1.11022302462516E-16 -7.63278329429795E-17"
        rpy="0 0 0" />
      <mass
        value="0.00565486677646163" />
      <inertia
        ixx="1.15924768917463E-07"
        ixy="-2.08628598142635E-20"
        ixz="-1.42085772761506E-20"
        iyy="1.89075183059975E-05"
        iyz="9.73135805409247E-38"
        izz="1.89075183059975E-05" />
    </inertial>
    <visual>
      <origin
        xyz="0 0 0"
        rpy="0 0 0" />
      <geometry>
        <mesh
          filename="package://ramp_meshes_1/meshes/right_hip_link.STL" />
      </geometry>
      <material
        name="">
        <color
          rgba="0.792156862745098 0.819607843137255 0.933333333333333 1" />
      </material>
    </visual>
    <collision>
      <origin
        xyz="0 0 0"
        rpy="0 0 0" />
      <geometry>
        <mesh
          filename="package://ramp_meshes_1/meshes/right_hip_link.STL" />
      </geometry>
    </collision>
  </link>
  <joint
    name="right_hip_joint"
    type="revolute">
    <origin
      xyz="0.0052304 0 0.188"
      rpy="-0.17453 0 0" />
    <parent
      link="right_upper_leg_link" />
    <child
      link="right_hip_link" />
    <axis
      xyz="-1 0 0" />
    <limit
      lower="0"
      upper="0"
      effort="0"
      velocity="0" />
  </joint>
  <link
    name="left_hip_link">
    <inertial>
      <origin
        xyz="-0.0383599176983876 0.0377734198436392 -0.0275215999400935"
        rpy="0 0 0" />
      <mass
        value="0.101399353812015" />
      <inertia
        ixx="0.000112959153864931"
        ixy="-4.46338507586178E-05"
        ixz="2.40701570964538E-05"
        iyy="0.000136800112572608"
        iyz="4.49100418656083E-05"
        izz="0.000189446793501919" />
    </inertial>
    <visual>
      <origin
        xyz="0 0 0"
        rpy="0 0 0" />
      <geometry>
        <mesh
          filename="package://ramp_meshes_1/meshes/left_hip_link.STL" />
      </geometry>
      <material
        name="">
        <color
          rgba="0.792156862745098 0.819607843137255 0.933333333333333 1" />
      </material>
    </visual>
    <collision>
      <origin
        xyz="0 0 0"
        rpy="0 0 0" />
      <geometry>
        <mesh
          filename="package://ramp_meshes_1/meshes/left_hip_link.STL" />
      </geometry>
    </collision>
  </link>
  <joint
    name="left_hip_joint"
    type="revolute">
    <origin
      xyz="-0.1 0 0"
      rpy="0 0 0" />
    <parent
      link="right_hip_link" />
    <child
      link="left_hip_link" />
    <axis
      xyz="-1 0 0" />
    <limit
      lower="0"
      upper="0"
      effort="0"
      velocity="0" />
  </joint>
  <link
    name="left_lower_leg_link">
    <inertial>
      <origin
        xyz="-0.0895053146451189 -0.136765391576967 -0.11007592605015"
        rpy="0 0 0" />
      <mass
        value="0.123883133217276" />
      <inertia
        ixx="0.000128415612995708"
        ixy="-4.6690406531709E-07"
        ixz="1.74067243659666E-06"
        iyy="0.000139960406795007"
        iyz="3.24863106602432E-05"
        izz="0.000100534618141724" />
    </inertial>
    <visual>
      <origin
        xyz="0 0 0"
        rpy="0 0 0" />
      <geometry>
        <mesh
          filename="package://ramp_meshes_1/meshes/left_lower_leg_link.STL" />
      </geometry>
      <material
        name="">
        <color
          rgba="0.792156862745098 0.819607843137255 0.933333333333333 1" />
      </material>
    </visual>
    <collision>
      <origin
        xyz="0 0 0"
        rpy="0 0 0" />
      <geometry>
        <mesh
          filename="package://ramp_meshes_1/meshes/left_lower_leg_link.STL" />
      </geometry>
    </collision>
  </link>
  <joint
    name="left_knee_joint"
    type="revolute">
    <origin
      xyz="0.014226 0.16281 -0.094"
      rpy="1.0472 0 0" />
    <parent
      link="left_hip_link" />
    <child
      link="left_lower_leg_link" />
    <axis
      xyz="1 0 0" />
    <limit
      lower="0"
      upper="1.57"
      effort="0"
      velocity="0" />
  </joint>
</robot>